Workbook
Name DeliveryDayList: DeliveryDays[Delivery_Day]
Name ProfileList: DemandProfile[Profile]
Name Weekday_List: WeekdayList[Weekday_List]

Sheet Instructions

Sheet Order_Planner
A2: Stocktake Day | B2: Sunday
A3: Next Delivery Day | B3: Monday
A4: Include delivery day in pre-demand? | B4: TRUE
A5: Demand Profile | B5: =Forecast_Model!E14 -> Normal
A8: Item | B8: Current Stock | C8: Incoming Ordered | D8: Order Qty | E8: Status | F8: Coverage Demand | G8: Adjusted Buffer | H8: Total Required | I8: Revenue at Risk | J8: Stock Runway Days | K8: Pre-Delivery Demand | L8: Projected Stock Delivery
A9: Sauce A | B9: 8 | C9: 1 | D9: =MAX(0, ROUNDUP(tPlan[[#This Row],[Total Required]] - (tPlan[[#This Row],[Current Stock]] + tPlan[[#This Row],[Incoming Ordered]]), 0)) -> 5 | E9: =IF(tPlan[[#This Row],[Projected Stock Delivery]]<=0,"URGENT", IF(tPlan[[#This Row],[Order Qty]]>0,"ORDER","OK")) -> ORDER | F9: {=_xlfn.LET( _xlpm.item, tPlan[[#This Row],[Item]], _xlpm.prof, $B$5, _xlpm.usageRow, _xlfn.XLOOKUP( _xlpm.item&"|"&_xlpm.prof, UsageProfiles[Item]&"|"&UsageProfiles[Profile], UsageProfiles[[Mon]:[Sun]], 0 ), _xlpm.effMultRow, _xlfn.XLOOKUP( {"Monday","Tuesday","Wednesday","Thursday","Friday","Saturday","Sunday"}, ForecastTbl[Weekday], ForecastTbl[Effective_Multiplier], 1 ), _xlpm.coverFlagsRow, _xlfn.XLOOKUP( $B$3, DeliveryCoverage[Delivery_Day], DeliveryCoverage[[Mon]:[Sun]], 0 ), SUMPRODUCT(_xlpm.usageRow, _xlpm.effMultRow, _xlpm.coverFlagsRow) )} -> 4.1780775 | G9: {=_xlfn.LET( _xlpm.item, tPlan[[#This Row],[Item]], _xlpm.prof, $B$5, _xlpm.baseBuffer, _xlfn.XLOOKUP( _xlpm.item&"|"&_xlpm.prof, UsageProfiles[Item]&"|"&UsageProfiles[Profile], UsageProfiles[Buffer], 0 ), _xlpm.profMult, Forecast_Model!$E$15, ROUNDUP(_xlpm.baseBuffer * _xlpm.profMult, 0) )} -> 3 | H9: =tPlan[[#This Row],[Pre-Delivery Demand]] + tPlan[[#This Row],[Coverage Demand]] + tPlan[[#This Row],[Adjusted Buffer]] -> 13.178078 | I9: {=_xlfn.LET( _xlpm.item, tPlan[[#This Row],[Item]], _xlpm.prof, $B$5, _xlpm.salesUnit, _xlfn.XLOOKUP( _xlpm.item&"|"&_xlpm.prof, UsageProfiles[Item]&"|"&UsageProfiles[Profile], UsageProfiles[Sales_per_unit], 0 ), MAX(0, tPlan[[#This Row],[Total Required]] - (tPlan[[#This Row],[Current Stock]] + tPlan[[#This Row],[Incoming Ordered]])) * _xlpm.salesUnit )} -> 2089.0388 | J9: {=_xlfn.LET( _xlpm.item, tPlan[[#This Row],[Item]], _xlpm.prof, $B$5, _xlpm.usageRow, _xlfn.XLOOKUP( _xlpm.item&"|"&_xlpm.prof, UsageProfiles[Item]&"|"&UsageProfiles[Profile], UsageProfiles[[Mon]:[Sun]], 0 ), _xlpm.effMultRow, _xlfn.XLOOKUP( {"Monday","Tuesday","Wednesday","Thursday","Friday","Saturday","Sunday"}, ForecastTbl[Weekday], ForecastTbl[Effective_Multiplier], 1 ), _xlpm.coverFlagsRow, _xlfn.XLOOKUP( $B$3, DeliveryCoverage[Delivery_Day], DeliveryCoverage[[Mon]:[Sun]], 0 ), _xlpm.covDays, SUM(_xlpm.coverFlagsRow), _xlpm.covDemand, SUMPRODUCT(_xlpm.usageRow, _xlpm.effMultRow, _xlpm.coverFlagsRow), _xlpm.dailyDemand, IF(_xlpm.covDays=0, 0, _xlpm.covDemand/_xlpm.covDays), IF(_xlpm.dailyDemand=0, "", ROUND((tPlan[[#This Row],[Current Stock]]+tPlan[[#This Row],[Incoming Ordered]])/_xlpm.dailyDemand, 1)) )} -> 4.3 | K9: {=ROUNDUP( _xlfn.LET( _xlpm.stDay, TRIM($B$2), _xlpm.delDay, TRIM($B$3), _xlpm.incDel, $B$4, _xlpm.dayNames, {"Monday","Tuesday","Wednesday","Thursday","Friday","Saturday","Sunday"}, _xlpm.idxSt, _xlfn.XMATCH(_xlpm.stDay, _xlpm.dayNames, 0), _xlpm.idxDel, _xlfn.XMATCH(_xlpm.delDay, _xlpm.dayNames, 0), _xlpm.days, {1,2,3,4,5,6,7}, _xlpm.idxEnd, IF(_xlpm.incDel, _xlpm.idxDel, _xlpm.idxDel-1), _xlpm.flags, IF( OR(ISNA(_xlpm.idxSt), ISNA(_xlpm.idxDel), _xlpm.idxEnd<1), {0,0,0,0,0,0,0}, IF( _xlpm.idxSt<=_xlpm.idxEnd, --(_xlpm.days>=_xlpm.idxSt)*(_xlpm.days<=_xlpm.idxEnd), --((_xlpm.days>=_xlpm.idxSt)+(_xlpm.days<=_xlpm.idxEnd)>0) ) ), _xlpm.usageRow, _xlfn.XLOOKUP( tPlan[[#This Row],[Item]]&"|"&$B$5, UsageProfiles[Item]&"|"&UsageProfiles[Profile], UsageProfiles[[Mon]:[Sun]], 0 ), _xlpm.effMultRow, _xlfn.XLOOKUP( _xlpm.dayNames, ForecastTbl[Weekday], ForecastTbl[Effective_Multiplier], 1 ), SUMPRODUCT(_xlpm.flags, _xlpm.usageRow, _xlpm.effMultRow) ), 0)} -> 6 | L9: =MAX(0, tPlan[[#This Row],[Current Stock]] - tPlan[[#This Row],[Pre-Delivery Demand]]) -> 2
A10: Frozen Item A | B10: 20 | C10: 5 | D10: =MAX(0, ROUNDUP(tPlan[[#This Row],[Total Required]] - (tPlan[[#This Row],[Current Stock]] + tPlan[[#This Row],[Incoming Ordered]]), 0)) -> 10 | E10: =IF(tPlan[[#This Row],[Projected Stock Delivery]]<=0,"URGENT", IF(tPlan[[#This Row],[Order Qty]]>0,"ORDER","OK")) -> ORDER | F10: {=_xlfn.LET( _xlpm.item, tPlan[[#This Row],[Item]], _xlpm.prof, $B$5, _xlpm.usageRow, _xlfn.XLOOKUP( _xlpm.item&"|"&_xlpm.prof, UsageProfiles[Item]&"|"&UsageProfiles[Profile], UsageProfiles[[Mon]:[Sun]], 0 ), _xlpm.effMultRow, _xlfn.XLOOKUP( {"Monday","Tuesday","Wednesday","Thursday","Friday","Saturday","Sunday"}, ForecastTbl[Weekday], ForecastTbl[Effective_Multiplier], 1 ), _xlpm.coverFlagsRow, _xlfn.XLOOKUP( $B$3, DeliveryCoverage[Delivery_Day], DeliveryCoverage[[Mon]:[Sun]], 0 ), SUMPRODUCT(_xlpm.usageRow, _xlpm.effMultRow, _xlpm.coverFlagsRow) )} -> 13.578752 | G10: {=_xlfn.LET( _xlpm.item, tPlan[[#This Row],[Item]], _xlpm.prof, $B$5, _xlpm.baseBuffer, _xlfn.XLOOKUP( _xlpm.item&"|"&_xlpm.prof, UsageProfiles[Item]&"|"&UsageProfiles[Profile], UsageProfiles[Buffer], 0 ), _xlpm.profMult, Forecast_Model!$E$15, ROUNDUP(_xlpm.baseBuffer * _xlpm.profMult, 0) )} -> 4 | H10: =tPlan[[#This Row],[Pre-Delivery Demand]] + tPlan[[#This Row],[Coverage Demand]] + tPlan[[#This Row],[Adjusted Buffer]] -> 34.578752 | I10: {=_xlfn.LET( _xlpm.item, tPlan[[#This Row],[Item]], _xlpm.prof, $B$5, _xlpm.salesUnit, _xlfn.XLOOKUP( _xlpm.item&"|"&_xlpm.prof, UsageProfiles[Item]&"|"&UsageProfiles[Profile], UsageProfiles[Sales_per_unit], 0 ), MAX(0, tPlan[[#This Row],[Total Required]] - (tPlan[[#This Row],[Current Stock]] + tPlan[[#This Row],[Incoming Ordered]])) * _xlpm.salesUnit )} -> 9578.752 | J10: {=_xlfn.LET( _xlpm.item, tPlan[[#This Row],[Item]], _xlpm.prof, $B$5, _xlpm.usageRow, _xlfn.XLOOKUP( _xlpm.item&"|"&_xlpm.prof, UsageProfiles[Item]&"|"&UsageProfiles[Profile], UsageProfiles[[Mon]:[Sun]], 0 ), _xlpm.effMultRow, _xlfn.XLOOKUP( {"Monday","Tuesday","Wednesday","Thursday","Friday","Saturday","Sunday"}, ForecastTbl[Weekday], ForecastTbl[Effective_Multiplier], 1 ), _xlpm.coverFlagsRow, _xlfn.XLOOKUP( $B$3, DeliveryCoverage[Delivery_Day], DeliveryCoverage[[Mon]:[Sun]], 0 ), _xlpm.covDays, SUM(_xlpm.coverFlagsRow), _xlpm.covDemand, SUMPRODUCT(_xlpm.usageRow, _xlpm.effMultRow, _xlpm.coverFlagsRow), _xlpm.dailyDemand, IF(_xlpm.covDays=0, 0, _xlpm.covDemand/_xlpm.covDays), IF(_xlpm.dailyDemand=0, "", ROUND((tPlan[[#This Row],[Current Stock]]+tPlan[[#This Row],[Incoming Ordered]])/_xlpm.dailyDemand, 1)) )} -> 3.7 | K10: {=ROUNDUP( _xlfn.LET( _xlpm.stDay, TRIM($B$2), _xlpm.delDay, TRIM($B$3), _xlpm.incDel, $B$4, _xlpm.dayNames, {"Monday","Tuesday","Wednesday","Thursday","Friday","Saturday","Sunday"}, _xlpm.idxSt, _xlfn.XMATCH(_xlpm.stDay, _xlpm.dayNames, 0), _xlpm.idxDel, _xlfn.XMATCH(_xlpm.delDay, _xlpm.dayNames, 0), _xlpm.days, {1,2,3,4,5,6,7}, _xlpm.idxEnd, IF(_xlpm.incDel, _xlpm.idxDel, _xlpm.idxDel-1), _xlpm.flags, IF( OR(ISNA(_xlpm.idxSt), ISNA(_xlpm.idxDel), _xlpm.idxEnd<1), {0,0,0,0,0,0,0}, IF( _xlpm.idxSt<=_xlpm.idxEnd, --(_xlpm.days>=_xlpm.idxSt)*(_xlpm.days<=_xlpm.idxEnd), --((_xlpm.days>=_xlpm.idxSt)+(_xlpm.days<=_xlpm.idxEnd)>0) ) ), _xlpm.usageRow, _xlfn.XLOOKUP( tPlan[[#This Row],[Item]]&"|"&$B$5, UsageProfiles[Item]&"|"&UsageProfiles[Profile], UsageProfiles[[Mon]:[Sun]], 0 ), _xlpm.effMultRow, _xlfn.XLOOKUP( _xlpm.dayNames, ForecastTbl[Weekday], ForecastTbl[Effective_Multiplier], 1 ), SUMPRODUCT(_xlpm.flags, _xlpm.usageRow, _xlpm.effMultRow) ), 0)} -> 17 | L10: =MAX(0, tPlan[[#This Row],[Current Stock]] - tPlan[[#This Row],[Pre-Delivery Demand]]) -> 3
A11: Bread Item A | B11: 8 | C11: 2 | D11: =MAX(0, ROUNDUP(tPlan[[#This Row],[Total Required]] - (tPlan[[#This Row],[Current Stock]] + tPlan[[#This Row],[Incoming Ordered]]), 0)) -> 5 | E11: =IF(tPlan[[#This Row],[Projected Stock Delivery]]<=0,"URGENT", IF(tPlan[[#This Row],[Order Qty]]>0,"ORDER","OK")) -> ORDER | F11: {=_xlfn.LET( _xlpm.item, tPlan[[#This Row],[Item]], _xlpm.prof, $B$5, _xlpm.usageRow, _xlfn.XLOOKUP( _xlpm.item&"|"&_xlpm.prof, UsageProfiles[Item]&"|"&UsageProfiles[Profile], UsageProfiles[[Mon]:[Sun]], 0 ), _xlpm.effMultRow, _xlfn.XLOOKUP( {"Monday","Tuesday","Wednesday","Thursday","Friday","Saturday","Sunday"}, ForecastTbl[Weekday], ForecastTbl[Effective_Multiplier], 1 ), _xlpm.coverFlagsRow, _xlfn.XLOOKUP( $B$3, DeliveryCoverage[Delivery_Day], DeliveryCoverage[[Mon]:[Sun]], 0 ), SUMPRODUCT(_xlpm.usageRow, _xlpm.effMultRow, _xlpm.coverFlagsRow) )} -> 4.1780775 | G11: {=_xlfn.LET( _xlpm.item, tPlan[[#This Row],[Item]], _xlpm.prof, $B$5, _xlpm.baseBuffer, _xlfn.XLOOKUP( _xlpm.item&"|"&_xlpm.prof, UsageProfiles[Item]&"|"&UsageProfiles[Profile], UsageProfiles[Buffer], 0 ), _xlpm.profMult, Forecast_Model!$E$15, ROUNDUP(_xlpm.baseBuffer * _xlpm.profMult, 0) )} -> 4 | H11: =tPlan[[#This Row],[Pre-Delivery Demand]] + tPlan[[#This Row],[Coverage Demand]] + tPlan[[#This Row],[Adjusted Buffer]] -> 14.178078 | I11: {=_xlfn.LET( _xlpm.item, tPlan[[#This Row],[Item]], _xlpm.prof, $B$5, _xlpm.salesUnit, _xlfn.XLOOKUP( _xlpm.item&"|"&_xlpm.prof, UsageProfiles[Item]&"|"&UsageProfiles[Profile], UsageProfiles[Sales_per_unit], 0 ), MAX(0, tPlan[[#This Row],[Total Required]] - (tPlan[[#This Row],[Current Stock]] + tPlan[[#This Row],[Incoming Ordered]])) * _xlpm.salesUnit )} -> 1880.1349 | J11: {=_xlfn.LET( _xlpm.item, tPlan[[#This Row],[Item]], _xlpm.prof, $B$5, _xlpm.usageRow, _xlfn.XLOOKUP( _xlpm.item&"|"&_xlpm.prof, UsageProfiles[Item]&"|"&UsageProfiles[Profile], UsageProfiles[[Mon]:[Sun]], 0 ), _xlpm.effMultRow, _xlfn.XLOOKUP( {"Monday","Tuesday","Wednesday","Thursday","Friday","Saturday","Sunday"}, ForecastTbl[Weekday], ForecastTbl[Effective_Multiplier], 1 ), _xlpm.coverFlagsRow, _xlfn.XLOOKUP( $B$3, DeliveryCoverage[Delivery_Day], DeliveryCoverage[[Mon]:[Sun]], 0 ), _xlpm.covDays, SUM(_xlpm.coverFlagsRow), _xlpm.covDemand, SUMPRODUCT(_xlpm.usageRow, _xlpm.effMultRow, _xlpm.coverFlagsRow), _xlpm.dailyDemand, IF(_xlpm.covDays=0, 0, _xlpm.covDemand/_xlpm.covDays), IF(_xlpm.dailyDemand=0, "", ROUND((tPlan[[#This Row],[Current Stock]]+tPlan[[#This Row],[Incoming Ordered]])/_xlpm.dailyDemand, 1)) )} -> 4.8 | K11: {=ROUNDUP( _xlfn.LET( _xlpm.stDay, TRIM($B$2), _xlpm.delDay, TRIM($B$3), _xlpm.incDel, $B$4, _xlpm.dayNames, {"Monday","Tuesday","Wednesday","Thursday","Friday","Saturday","Sunday"}, _xlpm.idxSt, _xlfn.XMATCH(_xlpm.stDay, _xlpm.dayNames, 0), _xlpm.idxDel, _xlfn.XMATCH(_xlpm.delDay, _xlpm.dayNames, 0), _xlpm.days, {1,2,3,4,5,6,7}, _xlpm.idxEnd, IF(_xlpm.incDel, _xlpm.idxDel, _xlpm.idxDel-1), _xlpm.flags, IF( OR(ISNA(_xlpm.idxSt), ISNA(_xlpm.idxDel), _xlpm.idxEnd<1), {0,0,0,0,0,0,0}, IF( _xlpm.idxSt<=_xlpm.idxEnd, --(_xlpm.days>=_xlpm.idxSt)*(_xlpm.days<=_xlpm.idxEnd), --((_xlpm.days>=_xlpm.idxSt)+(_xlpm.days<=_xlpm.idxEnd)>0) ) ), _xlpm.usageRow, _xlfn.XLOOKUP( tPlan[[#This Row],[Item]]&"|"&$B$5, UsageProfiles[Item]&"|"&UsageProfiles[Profile], UsageProfiles[[Mon]:[Sun]], 0 ), _xlpm.effMultRow, _xlfn.XLOOKUP( _xlpm.dayNames, ForecastTbl[Weekday], ForecastTbl[Effective_Multiplier], 1 ), SUMPRODUCT(_xlpm.flags, _xlpm.usageRow, _xlpm.effMultRow) ), 0)} -> 6 | L11: =MAX(0, tPlan[[#This Row],[Current Stock]] - tPlan[[#This Row],[Pre-Delivery Demand]]) -> 2
A12: Mix Item A | B12: 15 | C12: 8 | D12: =MAX(0, ROUNDUP(tPlan[[#This Row],[Total Required]] - (tPlan[[#This Row],[Current Stock]] + tPlan[[#This Row],[Incoming Ordered]]), 0)) -> 0 | E12: =IF(tPlan[[#This Row],[Projected Stock Delivery]]<=0,"URGENT", IF(tPlan[[#This Row],[Order Qty]]>0,"ORDER","OK")) -> OK | F12: {=_xlfn.LET( _xlpm.item, tPlan[[#This Row],[Item]], _xlpm.prof, $B$5, _xlpm.usageRow, _xlfn.XLOOKUP( _xlpm.item&"|"&_xlpm.prof, UsageProfiles[Item]&"|"&UsageProfiles[Profile], UsageProfiles[[Mon]:[Sun]], 0 ), _xlpm.effMultRow, _xlfn.XLOOKUP( {"Monday","Tuesday","Wednesday","Thursday","Friday","Saturday","Sunday"}, ForecastTbl[Weekday], ForecastTbl[Effective_Multiplier], 1 ), _xlpm.coverFlagsRow, _xlfn.XLOOKUP( $B$3, DeliveryCoverage[Delivery_Day], DeliveryCoverage[[Mon]:[Sun]], 0 ), SUMPRODUCT(_xlpm.usageRow, _xlpm.effMultRow, _xlpm.coverFlagsRow) )} -> 6.2671163 | G12: {=_xlfn.LET( _xlpm.item, tPlan[[#This Row],[Item]], _xlpm.prof, $B$5, _xlpm.baseBuffer, _xlfn.XLOOKUP( _xlpm.item&"|"&_xlpm.prof, UsageProfiles[Item]&"|"&UsageProfiles[Profile], UsageProfiles[Buffer], 0 ), _xlpm.profMult, Forecast_Model!$E$15, ROUNDUP(_xlpm.baseBuffer * _xlpm.profMult, 0) )} -> 5 | H12: =tPlan[[#This Row],[Pre-Delivery Demand]] + tPlan[[#This Row],[Coverage Demand]] + tPlan[[#This Row],[Adjusted Buffer]] -> 19.267116 | I12: {=_xlfn.LET( _xlpm.item, tPlan[[#This Row],[Item]], _xlpm.prof, $B$5, _xlpm.salesUnit, _xlfn.XLOOKUP( _xlpm.item&"|"&_xlpm.prof, UsageProfiles[Item]&"|"&UsageProfiles[Profile], UsageProfiles[Sales_per_unit], 0 ), MAX(0, tPlan[[#This Row],[Total Required]] - (tPlan[[#This Row],[Current Stock]] + tPlan[[#This Row],[Incoming Ordered]])) * _xlpm.salesUnit )} -> 0 | J12: {=_xlfn.LET( _xlpm.item, tPlan[[#This Row],[Item]], _xlpm.prof, $B$5, _xlpm.usageRow, _xlfn.XLOOKUP( _xlpm.item&"|"&_xlpm.prof, UsageProfiles[Item]&"|"&UsageProfiles[Profile], UsageProfiles[[Mon]:[Sun]], 0 ), _xlpm.effMultRow, _xlfn.XLOOKUP( {"Monday","Tuesday","Wednesday","Thursday","Friday","Saturday","Sunday"}, ForecastTbl[Weekday], ForecastTbl[Effective_Multiplier], 1 ), _xlpm.coverFlagsRow, _xlfn.XLOOKUP( $B$3, DeliveryCoverage[Delivery_Day], DeliveryCoverage[[Mon]:[Sun]], 0 ), _xlpm.covDays, SUM(_xlpm.coverFlagsRow), _xlpm.covDemand, SUMPRODUCT(_xlpm.usageRow, _xlpm.effMultRow, _xlpm.coverFlagsRow), _xlpm.dailyDemand, IF(_xlpm.covDays=0, 0, _xlpm.covDemand/_xlpm.covDays), IF(_xlpm.dailyDemand=0, "", ROUND((tPlan[[#This Row],[Current Stock]]+tPlan[[#This Row],[Incoming Ordered]])/_xlpm.dailyDemand, 1)) )} -> 7.3 | K12: {=ROUNDUP( _xlfn.LET( _xlpm.stDay, TRIM($B$2), _xlpm.delDay, TRIM($B$3), _xlpm.incDel, $B$4, _xlpm.dayNames, {"Monday","Tuesday","Wednesday","Thursday","Friday","Saturday","Sunday"}, _xlpm.idxSt, _xlfn.XMATCH(_xlpm.stDay, _xlpm.dayNames, 0), _xlpm.idxDel, _xlfn.XMATCH(_xlpm.delDay, _xlpm.dayNames, 0), _xlpm.days, {1,2,3,4,5,6,7}, _xlpm.idxEnd, IF(_xlpm.incDel, _xlpm.idxDel, _xlpm.idxDel-1), _xlpm.flags, IF( OR(ISNA(_xlpm.idxSt), ISNA(_xlpm.idxDel), _xlpm.idxEnd<1), {0,0,0,0,0,0,0}, IF( _xlpm.idxSt<=_xlpm.idxEnd, --(_xlpm.days>=_xlpm.idxSt)*(_xlpm.days<=_xlpm.idxEnd), --((_xlpm.days>=_xlpm.idxSt)+(_xlpm.days<=_xlpm.idxEnd)>0) ) ), _xlpm.usageRow, _xlfn.XLOOKUP( tPlan[[#This Row],[Item]]&"|"&$B$5, UsageProfiles[Item]&"|"&UsageProfiles[Profile], UsageProfiles[[Mon]:[Sun]], 0 ), _xlpm.effMultRow, _xlfn.XLOOKUP( _xlpm.dayNames, ForecastTbl[Weekday], ForecastTbl[Effective_Multiplier], 1 ), SUMPRODUCT(_xlpm.flags, _xlpm.usageRow, _xlpm.effMultRow) ), 0)} -> 8 | L12: =MAX(0, tPlan[[#This Row],[Current Stock]] - tPlan[[#This Row],[Pre-Delivery Demand]]) -> 7
A13: Packaging Item A | B13: 6 | C13: 2 | D13: =MAX(0, ROUNDUP(tPlan[[#This Row],[Total Required]] - (tPlan[[#This Row],[Current Stock]] + tPlan[[#This Row],[Incoming Ordered]]), 0)) -> 7 | E13: =IF(tPlan[[#This Row],[Projected Stock Delivery]]<=0,"URGENT", IF(tPlan[[#This Row],[Order Qty]]>0,"ORDER","OK")) -> URGENT | F13: {=_xlfn.LET( _xlpm.item, tPlan[[#This Row],[Item]], _xlpm.prof, $B$5, _xlpm.usageRow, _xlfn.XLOOKUP( _xlpm.item&"|"&_xlpm.prof, UsageProfiles[Item]&"|"&UsageProfiles[Profile], UsageProfiles[[Mon]:[Sun]], 0 ), _xlpm.effMultRow, _xlfn.XLOOKUP( {"Monday","Tuesday","Wednesday","Thursday","Friday","Saturday","Sunday"}, ForecastTbl[Weekday], ForecastTbl[Effective_Multiplier], 1 ), _xlpm.coverFlagsRow, _xlfn.XLOOKUP( $B$3, DeliveryCoverage[Delivery_Day], DeliveryCoverage[[Mon]:[Sun]], 0 ), SUMPRODUCT(_xlpm.usageRow, _xlpm.effMultRow, _xlpm.coverFlagsRow) )} -> 4.1780775 | G13: {=_xlfn.LET( _xlpm.item, tPlan[[#This Row],[Item]], _xlpm.prof, $B$5, _xlpm.baseBuffer, _xlfn.XLOOKUP( _xlpm.item&"|"&_xlpm.prof, UsageProfiles[Item]&"|"&UsageProfiles[Profile], UsageProfiles[Buffer], 0 ), _xlpm.profMult, Forecast_Model!$E$15, ROUNDUP(_xlpm.baseBuffer * _xlpm.profMult, 0) )} -> 4 | H13: =tPlan[[#This Row],[Pre-Delivery Demand]] + tPlan[[#This Row],[Coverage Demand]] + tPlan[[#This Row],[Adjusted Buffer]] -> 14.178078 | I13: {=_xlfn.LET( _xlpm.item, tPlan[[#This Row],[Item]], _xlpm.prof, $B$5, _xlpm.salesUnit, _xlfn.XLOOKUP( _xlpm.item&"|"&_xlpm.prof, UsageProfiles[Item]&"|"&UsageProfiles[Profile], UsageProfiles[Sales_per_unit], 0 ), MAX(0, tPlan[[#This Row],[Total Required]] - (tPlan[[#This Row],[Current Stock]] + tPlan[[#This Row],[Incoming Ordered]])) * _xlpm.salesUnit )} -> 926.71163 | J13: {=_xlfn.LET( _xlpm.item, tPlan[[#This Row],[Item]], _xlpm.prof, $B$5, _xlpm.usageRow, _xlfn.XLOOKUP( _xlpm.item&"|"&_xlpm.prof, UsageProfiles[Item]&"|"&UsageProfiles[Profile], UsageProfiles[[Mon]:[Sun]], 0 ), _xlpm.effMultRow, _xlfn.XLOOKUP( {"Monday","Tuesday","Wednesday","Thursday","Friday","Saturday","Sunday"}, ForecastTbl[Weekday], ForecastTbl[Effective_Multiplier], 1 ), _xlpm.coverFlagsRow, _xlfn.XLOOKUP( $B$3, DeliveryCoverage[Delivery_Day], DeliveryCoverage[[Mon]:[Sun]], 0 ), _xlpm.covDays, SUM(_xlpm.coverFlagsRow), _xlpm.covDemand, SUMPRODUCT(_xlpm.usageRow, _xlpm.effMultRow, _xlpm.coverFlagsRow), _xlpm.dailyDemand, IF(_xlpm.covDays=0, 0, _xlpm.covDemand/_xlpm.covDays), IF(_xlpm.dailyDemand=0, "", ROUND((tPlan[[#This Row],[Current Stock]]+tPlan[[#This Row],[Incoming Ordered]])/_xlpm.dailyDemand, 1)) )} -> 3.8 | K13: {=ROUNDUP( _xlfn.LET( _xlpm.stDay, TRIM($B$2), _xlpm.delDay, TRIM($B$3), _xlpm.incDel, $B$4, _xlpm.dayNames, {"Monday","Tuesday","Wednesday","Thursday","Friday","Saturday","Sunday"}, _xlpm.idxSt, _xlfn.XMATCH(_xlpm.stDay, _xlpm.dayNames, 0), _xlpm.idxDel, _xlfn.XMATCH(_xlpm.delDay, _xlpm.dayNames, 0), _xlpm.days, {1,2,3,4,5,6,7}, _xlpm.idxEnd, IF(_xlpm.incDel, _xlpm.idxDel, _xlpm.idxDel-1), _xlpm.flags, IF( OR(ISNA(_xlpm.idxSt), ISNA(_xlpm.idxDel), _xlpm.idxEnd<1), {0,0,0,0,0,0,0}, IF( _xlpm.idxSt<=_xlpm.idxEnd, --(_xlpm.days>=_xlpm.idxSt)*(_xlpm.days<=_xlpm.idxEnd), --((_xlpm.days>=_xlpm.idxSt)+(_xlpm.days<=_xlpm.idxEnd)>0) ) ), _xlpm.usageRow, _xlfn.XLOOKUP( tPlan[[#This Row],[Item]]&"|"&$B$5, UsageProfiles[Item]&"|"&UsageProfiles[Profile], UsageProfiles[[Mon]:[Sun]], 0 ), _xlpm.effMultRow, _xlfn.XLOOKUP( _xlpm.dayNames, ForecastTbl[Weekday], ForecastTbl[Effective_Multiplier], 1 ), SUMPRODUCT(_xlpm.flags, _xlpm.usageRow, _xlpm.effMultRow) ), 0)} -> 6 | L13: =MAX(0, tPlan[[#This Row],[Current Stock]] - tPlan[[#This Row],[Pre-Delivery Demand]]) -> 0
A14: Ingredient A | B14: 6 | C14: 2 | D14: =MAX(0, ROUNDUP(tPlan[[#This Row],[Total Required]] - (tPlan[[#This Row],[Current Stock]] + tPlan[[#This Row],[Incoming Ordered]]), 0)) -> 0 | E14: =IF(tPlan[[#This Row],[Projected Stock Delivery]]<=0,"URGENT", IF(tPlan[[#This Row],[Order Qty]]>0,"ORDER","OK")) -> OK | F14: {=_xlfn.LET( _xlpm.item, tPlan[[#This Row],[Item]], _xlpm.prof, $B$5, _xlpm.usageRow, _xlfn.XLOOKUP( _xlpm.item&"|"&_xlpm.prof, UsageProfiles[Item]&"|"&UsageProfiles[Profile], UsageProfiles[[Mon]:[Sun]], 0 ), _xlpm.effMultRow, _xlfn.XLOOKUP( {"Monday","Tuesday","Wednesday","Thursday","Friday","Saturday","Sunday"}, ForecastTbl[Weekday], ForecastTbl[Effective_Multiplier], 1 ), _xlpm.coverFlagsRow, _xlfn.XLOOKUP( $B$3, DeliveryCoverage[Delivery_Day], DeliveryCoverage[[Mon]:[Sun]], 0 ), SUMPRODUCT(_xlpm.usageRow, _xlpm.effMultRow, _xlpm.coverFlagsRow) )} -> 1.775683 | G14: {=_xlfn.LET( _xlpm.item, tPlan[[#This Row],[Item]], _xlpm.prof, $B$5, _xlpm.baseBuffer, _xlfn.XLOOKUP( _xlpm.item&"|"&_xlpm.prof, UsageProfiles[Item]&"|"&UsageProfiles[Profile], UsageProfiles[Buffer], 0 ), _xlpm.profMult, Forecast_Model!$E$15, ROUNDUP(_xlpm.baseBuffer * _xlpm.profMult, 0) )} -> 2 | H14: =tPlan[[#This Row],[Pre-Delivery Demand]] + tPlan[[#This Row],[Coverage Demand]] + tPlan[[#This Row],[Adjusted Buffer]] -> 6.775683 | I14: {=_xlfn.LET( _xlpm.item, tPlan[[#This Row],[Item]], _xlpm.prof, $B$5, _xlpm.salesUnit, _xlfn.XLOOKUP( _xlpm.item&"|"&_xlpm.prof, UsageProfiles[Item]&"|"&UsageProfiles[Profile], UsageProfiles[Sales_per_unit], 0 ), MAX(0, tPlan[[#This Row],[Total Required]] - (tPlan[[#This Row],[Current Stock]] + tPlan[[#This Row],[Incoming Ordered]])) * _xlpm.salesUnit )} -> 0 | J14: {=_xlfn.LET( _xlpm.item, tPlan[[#This Row],[Item]], _xlpm.prof, $B$5, _xlpm.usageRow, _xlfn.XLOOKUP( _xlpm.item&"|"&_xlpm.prof, UsageProfiles[Item]&"|"&UsageProfiles[Profile], UsageProfiles[[Mon]:[Sun]], 0 ), _xlpm.effMultRow, _xlfn.XLOOKUP( {"Monday","Tuesday","Wednesday","Thursday","Friday","Saturday","Sunday"}, ForecastTbl[Weekday], ForecastTbl[Effective_Multiplier], 1 ), _xlpm.coverFlagsRow, _xlfn.XLOOKUP( $B$3, DeliveryCoverage[Delivery_Day], DeliveryCoverage[[Mon]:[Sun]], 0 ), _xlpm.covDays, SUM(_xlpm.coverFlagsRow), _xlpm.covDemand, SUMPRODUCT(_xlpm.usageRow, _xlpm.effMultRow, _xlpm.coverFlagsRow), _xlpm.dailyDemand, IF(_xlpm.covDays=0, 0, _xlpm.covDemand/_xlpm.covDays), IF(_xlpm.dailyDemand=0, "", ROUND((tPlan[[#This Row],[Current Stock]]+tPlan[[#This Row],[Incoming Ordered]])/_xlpm.dailyDemand, 1)) )} -> 9 | K14: {=ROUNDUP( _xlfn.LET( _xlpm.stDay, TRIM($B$2), _xlpm.delDay, TRIM($B$3), _xlpm.incDel, $B$4, _xlpm.dayNames, {"Monday","Tuesday","Wednesday","Thursday","Friday","Saturday","Sunday"}, _xlpm.idxSt, _xlfn.XMATCH(_xlpm.stDay, _xlpm.dayNames, 0), _xlpm.idxDel, _xlfn.XMATCH(_xlpm.delDay, _xlpm.dayNames, 0), _xlpm.days, {1,2,3,4,5,6,7}, _xlpm.idxEnd, IF(_xlpm.incDel, _xlpm.idxDel, _xlpm.idxDel-1), _xlpm.flags, IF( OR(ISNA(_xlpm.idxSt), ISNA(_xlpm.idxDel), _xlpm.idxEnd<1), {0,0,0,0,0,0,0}, IF( _xlpm.idxSt<=_xlpm.idxEnd, --(_xlpm.days>=_xlpm.idxSt)*(_xlpm.days<=_xlpm.idxEnd), --((_xlpm.days>=_xlpm.idxSt)+(_xlpm.days<=_xlpm.idxEnd)>0) ) ), _xlpm.usageRow, _xlfn.XLOOKUP( tPlan[[#This Row],[Item]]&"|"&$B$5, UsageProfiles[Item]&"|"&UsageProfiles[Profile], UsageProfiles[[Mon]:[Sun]], 0 ), _xlpm.effMultRow, _xlfn.XLOOKUP( _xlpm.dayNames, ForecastTbl[Weekday], ForecastTbl[Effective_Multiplier], 1 ), SUMPRODUCT(_xlpm.flags, _xlpm.usageRow, _xlpm.effMultRow) ), 0)} -> 3 | L14: =MAX(0, tPlan[[#This Row],[Current Stock]] - tPlan[[#This Row],[Pre-Delivery Demand]]) -> 3
A15: Ingredient B | B15: 8 | C15: 6 | D15: =MAX(0, ROUNDUP(tPlan[[#This Row],[Total Required]] - (tPlan[[#This Row],[Current Stock]] + tPlan[[#This Row],[Incoming Ordered]]), 0)) -> 1 | E15: =IF(tPlan[[#This Row],[Projected Stock Delivery]]<=0,"URGENT", IF(tPlan[[#This Row],[Order Qty]]>0,"ORDER","OK")) -> ORDER | F15: {=_xlfn.LET( _xlpm.item, tPlan[[#This Row],[Item]], _xlpm.prof, $B$5, _xlpm.usageRow, _xlfn.XLOOKUP( _xlpm.item&"|"&_xlpm.prof, UsageProfiles[Item]&"|"&UsageProfiles[Profile], UsageProfiles[[Mon]:[Sun]], 0 ), _xlpm.effMultRow, _xlfn.XLOOKUP( {"Monday","Tuesday","Wednesday","Thursday","Friday","Saturday","Sunday"}, ForecastTbl[Weekday], ForecastTbl[Effective_Multiplier], 1 ), _xlpm.coverFlagsRow, _xlfn.XLOOKUP( $B$3, DeliveryCoverage[Delivery_Day], DeliveryCoverage[[Mon]:[Sun]], 0 ), SUMPRODUCT(_xlpm.usageRow, _xlpm.effMultRow, _xlpm.coverFlagsRow) )} -> 4.1780775 | G15: {=_xlfn.LET( _xlpm.item, tPlan[[#This Row],[Item]], _xlpm.prof, $B$5, _xlpm.baseBuffer, _xlfn.XLOOKUP( _xlpm.item&"|"&_xlpm.prof, UsageProfiles[Item]&"|"&UsageProfiles[Profile], UsageProfiles[Buffer], 0 ), _xlpm.profMult, Forecast_Model!$E$15, ROUNDUP(_xlpm.baseBuffer * _xlpm.profMult, 0) )} -> 4 | H15: =tPlan[[#This Row],[Pre-Delivery Demand]] + tPlan[[#This Row],[Coverage Demand]] + tPlan[[#This Row],[Adjusted Buffer]] -> 14.178078 | I15: {=_xlfn.LET( _xlpm.item, tPlan[[#This Row],[Item]], _xlpm.prof, $B$5, _xlpm.salesUnit, _xlfn.XLOOKUP( _xlpm.item&"|"&_xlpm.prof, UsageProfiles[Item]&"|"&UsageProfiles[Profile], UsageProfiles[Sales_per_unit], 0 ), MAX(0, tPlan[[#This Row],[Total Required]] - (tPlan[[#This Row],[Current Stock]] + tPlan[[#This Row],[Incoming Ordered]])) * _xlpm.salesUnit )} -> 186.98142 | J15: {=_xlfn.LET( _xlpm.item, tPlan[[#This Row],[Item]], _xlpm.prof, $B$5, _xlpm.usageRow, _xlfn.XLOOKUP( _xlpm.item&"|"&_xlpm.prof, UsageProfiles[Item]&"|"&UsageProfiles[Profile], UsageProfiles[[Mon]:[Sun]], 0 ), _xlpm.effMultRow, _xlfn.XLOOKUP( {"Monday","Tuesday","Wednesday","Thursday","Friday","Saturday","Sunday"}, ForecastTbl[Weekday], ForecastTbl[Effective_Multiplier], 1 ), _xlpm.coverFlagsRow, _xlfn.XLOOKUP( $B$3, DeliveryCoverage[Delivery_Day], DeliveryCoverage[[Mon]:[Sun]], 0 ), _xlpm.covDays, SUM(_xlpm.coverFlagsRow), _xlpm.covDemand, SUMPRODUCT(_xlpm.usageRow, _xlpm.effMultRow, _xlpm.coverFlagsRow), _xlpm.dailyDemand, IF(_xlpm.covDays=0, 0, _xlpm.covDemand/_xlpm.covDays), IF(_xlpm.dailyDemand=0, "", ROUND((tPlan[[#This Row],[Current Stock]]+tPlan[[#This Row],[Incoming Ordered]])/_xlpm.dailyDemand, 1)) )} -> 6.7 | K15: {=ROUNDUP( _xlfn.LET( _xlpm.stDay, TRIM($B$2), _xlpm.delDay, TRIM($B$3), _xlpm.incDel, $B$4, _xlpm.dayNames, {"Monday","Tuesday","Wednesday","Thursday","Friday","Saturday","Sunday"}, _xlpm.idxSt, _xlfn.XMATCH(_xlpm.stDay, _xlpm.dayNames, 0), _xlpm.idxDel, _xlfn.XMATCH(_xlpm.delDay, _xlpm.dayNames, 0), _xlpm.days, {1,2,3,4,5,6,7}, _xlpm.idxEnd, IF(_xlpm.incDel, _xlpm.idxDel, _xlpm.idxDel-1), _xlpm.flags, IF( OR(ISNA(_xlpm.idxSt), ISNA(_xlpm.idxDel), _xlpm.idxEnd<1), {0,0,0,0,0,0,0}, IF( _xlpm.idxSt<=_xlpm.idxEnd, --(_xlpm.days>=_xlpm.idxSt)*(_xlpm.days<=_xlpm.idxEnd), --((_xlpm.days>=_xlpm.idxSt)+(_xlpm.days<=_xlpm.idxEnd)>0) ) ), _xlpm.usageRow, _xlfn.XLOOKUP( tPlan[[#This Row],[Item]]&"|"&$B$5, UsageProfiles[Item]&"|"&UsageProfiles[Profile], UsageProfiles[[Mon]:[Sun]], 0 ), _xlpm.effMultRow, _xlfn.XLOOKUP( _xlpm.dayNames, ForecastTbl[Weekday], ForecastTbl[Effective_Multiplier], 1 ), SUMPRODUCT(_xlpm.flags, _xlpm.usageRow, _xlpm.effMultRow) ), 0)} -> 6 | L15: =MAX(0, tPlan[[#This Row],[Current Stock]] - tPlan[[#This Row],[Pre-Delivery Demand]]) -> 2
A16: Dairy Item A | B16: 1 | C16: 2 | D16: =MAX(0, ROUNDUP(tPlan[[#This Row],[Total Required]] - (tPlan[[#This Row],[Current Stock]] + tPlan[[#This Row],[Incoming Ordered]]), 0)) -> 3 | E16: =IF(tPlan[[#This Row],[Projected Stock Delivery]]<=0,"URGENT", IF(tPlan[[#This Row],[Order Qty]]>0,"ORDER","OK")) -> URGENT | F16: {=_xlfn.LET( _xlpm.item, tPlan[[#This Row],[Item]], _xlpm.prof, $B$5, _xlpm.usageRow, _xlfn.XLOOKUP( _xlpm.item&"|"&_xlpm.prof, UsageProfiles[Item]&"|"&UsageProfiles[Profile], UsageProfiles[[Mon]:[Sun]], 0 ), _xlpm.effMultRow, _xlfn.XLOOKUP( {"Monday","Tuesday","Wednesday","Thursday","Friday","Saturday","Sunday"}, ForecastTbl[Weekday], ForecastTbl[Effective_Multiplier], 1 ), _xlpm.coverFlagsRow, _xlfn.XLOOKUP( $B$3, DeliveryCoverage[Delivery_Day], DeliveryCoverage[[Mon]:[Sun]], 0 ), SUMPRODUCT(_xlpm.usageRow, _xlpm.effMultRow, _xlpm.coverFlagsRow) )} -> 1.3578752 | G16: {=_xlfn.LET( _xlpm.item, tPlan[[#This Row],[Item]], _xlpm.prof, $B$5, _xlpm.baseBuffer, _xlfn.XLOOKUP( _xlpm.item&"|"&_xlpm.prof, UsageProfiles[Item]&"|"&UsageProfiles[Profile], UsageProfiles[Buffer], 0 ), _xlpm.profMult, Forecast_Model!$E$15, ROUNDUP(_xlpm.baseBuffer * _xlpm.profMult, 0) )} -> 2 | H16: =tPlan[[#This Row],[Pre-Delivery Demand]] + tPlan[[#This Row],[Coverage Demand]] + tPlan[[#This Row],[Adjusted Buffer]] -> 5.3578752 | I16: {=_xlfn.LET( _xlpm.item, tPlan[[#This Row],[Item]], _xlpm.prof, $B$5, _xlpm.salesUnit, _xlfn.XLOOKUP( _xlpm.item&"|"&_xlpm.prof, UsageProfiles[Item]&"|"&UsageProfiles[Profile], UsageProfiles[Sales_per_unit], 0 ), MAX(0, tPlan[[#This Row],[Total Required]] - (tPlan[[#This Row],[Current Stock]] + tPlan[[#This Row],[Incoming Ordered]])) * _xlpm.salesUnit )} -> 943.15008 | J16: {=_xlfn.LET( _xlpm.item, tPlan[[#This Row],[Item]], _xlpm.prof, $B$5, _xlpm.usageRow, _xlfn.XLOOKUP( _xlpm.item&"|"&_xlpm.prof, UsageProfiles[Item]&"|"&UsageProfiles[Profile], UsageProfiles[[Mon]:[Sun]], 0 ), _xlpm.effMultRow, _xlfn.XLOOKUP( {"Monday","Tuesday","Wednesday","Thursday","Friday","Saturday","Sunday"}, ForecastTbl[Weekday], ForecastTbl[Effective_Multiplier], 1 ), _xlpm.coverFlagsRow, _xlfn.XLOOKUP( $B$3, DeliveryCoverage[Delivery_Day], DeliveryCoverage[[Mon]:[Sun]], 0 ), _xlpm.covDays, SUM(_xlpm.coverFlagsRow), _xlpm.covDemand, SUMPRODUCT(_xlpm.usageRow, _xlpm.effMultRow, _xlpm.coverFlagsRow), _xlpm.dailyDemand, IF(_xlpm.covDays=0, 0, _xlpm.covDemand/_xlpm.covDays), IF(_xlpm.dailyDemand=0, "", ROUND((tPlan[[#This Row],[Current Stock]]+tPlan[[#This Row],[Incoming Ordered]])/_xlpm.dailyDemand, 1)) )} -> 4.4 | K16: {=ROUNDUP( _xlfn.LET( _xlpm.stDay, TRIM($B$2), _xlpm.delDay, TRIM($B$3), _xlpm.incDel, $B$4, _xlpm.dayNames, {"Monday","Tuesday","Wednesday","Thursday","Friday","Saturday","Sunday"}, _xlpm.idxSt, _xlfn.XMATCH(_xlpm.stDay, _xlpm.dayNames, 0), _xlpm.idxDel, _xlfn.XMATCH(_xlpm.delDay, _xlpm.dayNames, 0), _xlpm.days, {1,2,3,4,5,6,7}, _xlpm.idxEnd, IF(_xlpm.incDel, _xlpm.idxDel, _xlpm.idxDel-1), _xlpm.flags, IF( OR(ISNA(_xlpm.idxSt), ISNA(_xlpm.idxDel), _xlpm.idxEnd<1), {0,0,0,0,0,0,0}, IF( _xlpm.idxSt<=_xlpm.idxEnd, --(_xlpm.days>=_xlpm.idxSt)*(_xlpm.days<=_xlpm.idxEnd), --((_xlpm.days>=_xlpm.idxSt)+(_xlpm.days<=_xlpm.idxEnd)>0) ) ), _xlpm.usageRow, _xlfn.XLOOKUP( tPlan[[#This Row],[Item]]&"|"&$B$5, UsageProfiles[Item]&"|"&UsageProfiles[Profile], UsageProfiles[[Mon]:[Sun]], 0 ), _xlpm.effMultRow, _xlfn.XLOOKUP( _xlpm.dayNames, ForecastTbl[Weekday], ForecastTbl[Effective_Multiplier], 1 ), SUMPRODUCT(_xlpm.flags, _xlpm.usageRow, _xlpm.effMultRow) ), 0)} -> 2 | L16: =MAX(0, tPlan[[#This Row],[Current Stock]] - tPlan[[#This Row],[Pre-Delivery Demand]]) -> 0
A17: Gloves XL | B17: 3 | C17: 0 | D17: =MAX(0, ROUNDUP(tPlan[[#This Row],[Total Required]] - (tPlan[[#This Row],[Current Stock]] + tPlan[[#This Row],[Incoming Ordered]]), 0)) -> 1 | E17: =IF(tPlan[[#This Row],[Projected Stock Delivery]]<=0,"URGENT", IF(tPlan[[#This Row],[Order Qty]]>0,"ORDER","OK")) -> ORDER | F17: {=_xlfn.LET( _xlpm.item, tPlan[[#This Row],[Item]], _xlpm.prof, $B$5, _xlpm.usageRow, _xlfn.XLOOKUP( _xlpm.item&"|"&_xlpm.prof, UsageProfiles[Item]&"|"&UsageProfiles[Profile], UsageProfiles[[Mon]:[Sun]], 0 ), _xlpm.effMultRow, _xlfn.XLOOKUP( {"Monday","Tuesday","Wednesday","Thursday","Friday","Saturday","Sunday"}, ForecastTbl[Weekday], ForecastTbl[Effective_Multiplier], 1 ), _xlpm.coverFlagsRow, _xlfn.XLOOKUP( $B$3, DeliveryCoverage[Delivery_Day], DeliveryCoverage[[Mon]:[Sun]], 0 ), SUMPRODUCT(_xlpm.usageRow, _xlpm.effMultRow, _xlpm.coverFlagsRow) )} -> 1.0445194 | G17: {=_xlfn.LET( _xlpm.item, tPlan[[#This Row],[Item]], _xlpm.prof, $B$5, _xlpm.baseBuffer, _xlfn.XLOOKUP( _xlpm.item&"|"&_xlpm.prof, UsageProfiles[Item]&"|"&UsageProfiles[Profile], UsageProfiles[Buffer], 0 ), _xlpm.profMult, Forecast_Model!$E$15, ROUNDUP(_xlpm.baseBuffer * _xlpm.profMult, 0) )} -> 0 | H17: =tPlan[[#This Row],[Pre-Delivery Demand]] + tPlan[[#This Row],[Coverage Demand]] + tPlan[[#This Row],[Adjusted Buffer]] -> 3.0445194 | I17: {=_xlfn.LET( _xlpm.item, tPlan[[#This Row],[Item]], _xlpm.prof, $B$5, _xlpm.salesUnit, _xlfn.XLOOKUP( _xlpm.item&"|"&_xlpm.prof, UsageProfiles[Item]&"|"&UsageProfiles[Profile], UsageProfiles[Sales_per_unit], 0 ), MAX(0, tPlan[[#This Row],[Total Required]] - (tPlan[[#This Row],[Current Stock]] + tPlan[[#This Row],[Incoming Ordered]])) * _xlpm.salesUnit )} -> 0 | J17: {=_xlfn.LET( _xlpm.item, tPlan[[#This Row],[Item]], _xlpm.prof, $B$5, _xlpm.usageRow, _xlfn.XLOOKUP( _xlpm.item&"|"&_xlpm.prof, UsageProfiles[Item]&"|"&UsageProfiles[Profile], UsageProfiles[[Mon]:[Sun]], 0 ), _xlpm.effMultRow, _xlfn.XLOOKUP( {"Monday","Tuesday","Wednesday","Thursday","Friday","Saturday","Sunday"}, ForecastTbl[Weekday], ForecastTbl[Effective_Multiplier], 1 ), _xlpm.coverFlagsRow, _xlfn.XLOOKUP( $B$3, DeliveryCoverage[Delivery_Day], DeliveryCoverage[[Mon]:[Sun]], 0 ), _xlpm.covDays, SUM(_xlpm.coverFlagsRow), _xlpm.covDemand, SUMPRODUCT(_xlpm.usageRow, _xlpm.effMultRow, _xlpm.coverFlagsRow), _xlpm.dailyDemand, IF(_xlpm.covDays=0, 0, _xlpm.covDemand/_xlpm.covDays), IF(_xlpm.dailyDemand=0, "", ROUND((tPlan[[#This Row],[Current Stock]]+tPlan[[#This Row],[Incoming Ordered]])/_xlpm.dailyDemand, 1)) )} -> 5.7 | K17: {=ROUNDUP( _xlfn.LET( _xlpm.stDay, TRIM($B$2), _xlpm.delDay, TRIM($B$3), _xlpm.incDel, $B$4, _xlpm.dayNames, {"Monday","Tuesday","Wednesday","Thursday","Friday","Saturday","Sunday"}, _xlpm.idxSt, _xlfn.XMATCH(_xlpm.stDay, _xlpm.dayNames, 0), _xlpm.idxDel, _xlfn.XMATCH(_xlpm.delDay, _xlpm.dayNames, 0), _xlpm.days, {1,2,3,4,5,6,7}, _xlpm.idxEnd, IF(_xlpm.incDel, _xlpm.idxDel, _xlpm.idxDel-1), _xlpm.flags, IF( OR(ISNA(_xlpm.idxSt), ISNA(_xlpm.idxDel), _xlpm.idxEnd<1), {0,0,0,0,0,0,0}, IF( _xlpm.idxSt<=_xlpm.idxEnd, --(_xlpm.days>=_xlpm.idxSt)*(_xlpm.days<=_xlpm.idxEnd), --((_xlpm.days>=_xlpm.idxSt)+(_xlpm.days<=_xlpm.idxEnd)>0) ) ), _xlpm.usageRow, _xlfn.XLOOKUP( tPlan[[#This Row],[Item]]&"|"&$B$5, UsageProfiles[Item]&"|"&UsageProfiles[Profile], UsageProfiles[[Mon]:[Sun]], 0 ), _xlpm.effMultRow, _xlfn.XLOOKUP( _xlpm.dayNames, ForecastTbl[Weekday], ForecastTbl[Effective_Multiplier], 1 ), SUMPRODUCT(_xlpm.flags, _xlpm.usageRow, _xlpm.effMultRow) ), 0)} -> 2 | L17: =MAX(0, tPlan[[#This Row],[Current Stock]] - tPlan[[#This Row],[Pre-Delivery Demand]]) -> 1
A18: Gloves L | B18: 1 | C18: 0 | D18: =MAX(0, ROUNDUP(tPlan[[#This Row],[Total Required]] - (tPlan[[#This Row],[Current Stock]] + tPlan[[#This Row],[Incoming Ordered]]), 0)) -> 3 | E18: =IF(tPlan[[#This Row],[Projected Stock Delivery]]<=0,"URGENT", IF(tPlan[[#This Row],[Order Qty]]>0,"ORDER","OK")) -> URGENT | F18: {=_xlfn.LET( _xlpm.item, tPlan[[#This Row],[Item]], _xlpm.prof, $B$5, _xlpm.usageRow, _xlfn.XLOOKUP( _xlpm.item&"|"&_xlpm.prof, UsageProfiles[Item]&"|"&UsageProfiles[Profile], UsageProfiles[[Mon]:[Sun]], 0 ), _xlpm.effMultRow, _xlfn.XLOOKUP( {"Monday","Tuesday","Wednesday","Thursday","Friday","Saturday","Sunday"}, ForecastTbl[Weekday], ForecastTbl[Effective_Multiplier], 1 ), _xlpm.coverFlagsRow, _xlfn.XLOOKUP( $B$3, DeliveryCoverage[Delivery_Day], DeliveryCoverage[[Mon]:[Sun]], 0 ), SUMPRODUCT(_xlpm.usageRow, _xlpm.effMultRow, _xlpm.coverFlagsRow) )} -> 1.0445194 | G18: {=_xlfn.LET( _xlpm.item, tPlan[[#This Row],[Item]], _xlpm.prof, $B$5, _xlpm.baseBuffer, _xlfn.XLOOKUP( _xlpm.item&"|"&_xlpm.prof, UsageProfiles[Item]&"|"&UsageProfiles[Profile], UsageProfiles[Buffer], 0 ), _xlpm.profMult, Forecast_Model!$E$15, ROUNDUP(_xlpm.baseBuffer * _xlpm.profMult, 0) )} -> 0 | H18: =tPlan[[#This Row],[Pre-Delivery Demand]] + tPlan[[#This Row],[Coverage Demand]] + tPlan[[#This Row],[Adjusted Buffer]] -> 3.0445194 | I18: {=_xlfn.LET( _xlpm.item, tPlan[[#This Row],[Item]], _xlpm.prof, $B$5, _xlpm.salesUnit, _xlfn.XLOOKUP( _xlpm.item&"|"&_xlpm.prof, UsageProfiles[Item]&"|"&UsageProfiles[Profile], UsageProfiles[Sales_per_unit], 0 ), MAX(0, tPlan[[#This Row],[Total Required]] - (tPlan[[#This Row],[Current Stock]] + tPlan[[#This Row],[Incoming Ordered]])) * _xlpm.salesUnit )} -> 0 | J18: {=_xlfn.LET( _xlpm.item, tPlan[[#This Row],[Item]], _xlpm.prof, $B$5, _xlpm.usageRow, _xlfn.XLOOKUP( _xlpm.item&"|"&_xlpm.prof, UsageProfiles[Item]&"|"&UsageProfiles[Profile], UsageProfiles[[Mon]:[Sun]], 0 ), _xlpm.effMultRow, _xlfn.XLOOKUP( {"Monday","Tuesday","Wednesday","Thursday","Friday","Saturday","Sunday"}, ForecastTbl[Weekday], ForecastTbl[Effective_Multiplier], 1 ), _xlpm.coverFlagsRow, _xlfn.XLOOKUP( $B$3, DeliveryCoverage[Delivery_Day], DeliveryCoverage[[Mon]:[Sun]], 0 ), _xlpm.covDays, SUM(_xlpm.coverFlagsRow), _xlpm.covDemand, SUMPRODUCT(_xlpm.usageRow, _xlpm.effMultRow, _xlpm.coverFlagsRow), _xlpm.dailyDemand, IF(_xlpm.covDays=0, 0, _xlpm.covDemand/_xlpm.covDays), IF(_xlpm.dailyDemand=0, "", ROUND((tPlan[[#This Row],[Current Stock]]+tPlan[[#This Row],[Incoming Ordered]])/_xlpm.dailyDemand, 1)) )} -> 1.9 | K18: {=ROUNDUP( _xlfn.LET( _xlpm.stDay, TRIM($B$2), _xlpm.delDay, TRIM($B$3), _xlpm.incDel, $B$4, _xlpm.dayNames, {"Monday","Tuesday","Wednesday","Thursday","Friday","Saturday","Sunday"}, _xlpm.idxSt, _xlfn.XMATCH(_xlpm.stDay, _xlpm.dayNames, 0), _xlpm.idxDel, _xlfn.XMATCH(_xlpm.delDay, _xlpm.dayNames, 0), _xlpm.days, {1,2,3,4,5,6,7}, _xlpm.idxEnd, IF(_xlpm.incDel, _xlpm.idxDel, _xlpm.idxDel-1), _xlpm.flags, IF( OR(ISNA(_xlpm.idxSt), ISNA(_xlpm.idxDel), _xlpm.idxEnd<1), {0,0,0,0,0,0,0}, IF( _xlpm.idxSt<=_xlpm.idxEnd, --(_xlpm.days>=_xlpm.idxSt)*(_xlpm.days<=_xlpm.idxEnd), --((_xlpm.days>=_xlpm.idxSt)+(_xlpm.days<=_xlpm.idxEnd)>0) ) ), _xlpm.usageRow, _xlfn.XLOOKUP( tPlan[[#This Row],[Item]]&"|"&$B$5, UsageProfiles[Item]&"|"&UsageProfiles[Profile], UsageProfiles[[Mon]:[Sun]], 0 ), _xlpm.effMultRow, _xlfn.XLOOKUP( _xlpm.dayNames, ForecastTbl[Weekday], ForecastTbl[Effective_Multiplier], 1 ), SUMPRODUCT(_xlpm.flags, _xlpm.usageRow, _xlpm.effMultRow) ), 0)} -> 2 | L18: =MAX(0, tPlan[[#This Row],[Current Stock]] - tPlan[[#This Row],[Pre-Delivery Demand]]) -> 0
A19: Gloves M | B19: 4 | C19: 0 | D19: =MAX(0, ROUNDUP(tPlan[[#This Row],[Total Required]] - (tPlan[[#This Row],[Current Stock]] + tPlan[[#This Row],[Incoming Ordered]]), 0)) -> 0 | E19: =IF(tPlan[[#This Row],[Projected Stock Delivery]]<=0,"URGENT", IF(tPlan[[#This Row],[Order Qty]]>0,"ORDER","OK")) -> OK | F19: {=_xlfn.LET( _xlpm.item, tPlan[[#This Row],[Item]], _xlpm.prof, $B$5, _xlpm.usageRow, _xlfn.XLOOKUP( _xlpm.item&"|"&_xlpm.prof, UsageProfiles[Item]&"|"&UsageProfiles[Profile], UsageProfiles[[Mon]:[Sun]], 0 ), _xlpm.effMultRow, _xlfn.XLOOKUP( {"Monday","Tuesday","Wednesday","Thursday","Friday","Saturday","Sunday"}, ForecastTbl[Weekday], ForecastTbl[Effective_Multiplier], 1 ), _xlpm.coverFlagsRow, _xlfn.XLOOKUP( $B$3, DeliveryCoverage[Delivery_Day], DeliveryCoverage[[Mon]:[Sun]], 0 ), SUMPRODUCT(_xlpm.usageRow, _xlpm.effMultRow, _xlpm.coverFlagsRow) )} -> 1.0445194 | G19: {=_xlfn.LET( _xlpm.item, tPlan[[#This Row],[Item]], _xlpm.prof, $B$5, _xlpm.baseBuffer, _xlfn.XLOOKUP( _xlpm.item&"|"&_xlpm.prof, UsageProfiles[Item]&"|"&UsageProfiles[Profile], UsageProfiles[Buffer], 0 ), _xlpm.profMult, Forecast_Model!$E$15, ROUNDUP(_xlpm.baseBuffer * _xlpm.profMult, 0) )} -> 0 | H19: =tPlan[[#This Row],[Pre-Delivery Demand]] + tPlan[[#This Row],[Coverage Demand]] + tPlan[[#This Row],[Adjusted Buffer]] -> 3.0445194 | I19: {=_xlfn.LET( _xlpm.item, tPlan[[#This Row],[Item]], _xlpm.prof, $B$5, _xlpm.salesUnit, _xlfn.XLOOKUP( _xlpm.item&"|"&_xlpm.prof, UsageProfiles[Item]&"|"&UsageProfiles[Profile], UsageProfiles[Sales_per_unit], 0 ), MAX(0, tPlan[[#This Row],[Total Required]] - (tPlan[[#This Row],[Current Stock]] + tPlan[[#This Row],[Incoming Ordered]])) * _xlpm.salesUnit )} -> 0 | J19: {=_xlfn.LET( _xlpm.item, tPlan[[#This Row],[Item]], _xlpm.prof, $B$5, _xlpm.usageRow, _xlfn.XLOOKUP( _xlpm.item&"|"&_xlpm.prof, UsageProfiles[Item]&"|"&UsageProfiles[Profile], UsageProfiles[[Mon]:[Sun]], 0 ), _xlpm.effMultRow, _xlfn.XLOOKUP( {"Monday","Tuesday","Wednesday","Thursday","Friday","Saturday","Sunday"}, ForecastTbl[Weekday], ForecastTbl[Effective_Multiplier], 1 ), _xlpm.coverFlagsRow, _xlfn.XLOOKUP( $B$3, DeliveryCoverage[Delivery_Day], DeliveryCoverage[[Mon]:[Sun]], 0 ), _xlpm.covDays, SUM(_xlpm.coverFlagsRow), _xlpm.covDemand, SUMPRODUCT(_xlpm.usageRow, _xlpm.effMultRow, _xlpm.coverFlagsRow), _xlpm.dailyDemand, IF(_xlpm.covDays=0, 0, _xlpm.covDemand/_xlpm.covDays), IF(_xlpm.dailyDemand=0, "", ROUND((tPlan[[#This Row],[Current Stock]]+tPlan[[#This Row],[Incoming Ordered]])/_xlpm.dailyDemand, 1)) )} -> 7.7 | K19: {=ROUNDUP( _xlfn.LET( _xlpm.stDay, TRIM($B$2), _xlpm.delDay, TRIM($B$3), _xlpm.incDel, $B$4, _xlpm.dayNames, {"Monday","Tuesday","Wednesday","Thursday","Friday","Saturday","Sunday"}, _xlpm.idxSt, _xlfn.XMATCH(_xlpm.stDay, _xlpm.dayNames, 0), _xlpm.idxDel, _xlfn.XMATCH(_xlpm.delDay, _xlpm.dayNames, 0), _xlpm.days, {1,2,3,4,5,6,7}, _xlpm.idxEnd, IF(_xlpm.incDel, _xlpm.idxDel, _xlpm.idxDel-1), _xlpm.flags, IF( OR(ISNA(_xlpm.idxSt), ISNA(_xlpm.idxDel), _xlpm.idxEnd<1), {0,0,0,0,0,0,0}, IF( _xlpm.idxSt<=_xlpm.idxEnd, --(_xlpm.days>=_xlpm.idxSt)*(_xlpm.days<=_xlpm.idxEnd), --((_xlpm.days>=_xlpm.idxSt)+(_xlpm.days<=_xlpm.idxEnd)>0) ) ), _xlpm.usageRow, _xlfn.XLOOKUP( tPlan[[#This Row],[Item]]&"|"&$B$5, UsageProfiles[Item]&"|"&UsageProfiles[Profile], UsageProfiles[[Mon]:[Sun]], 0 ), _xlpm.effMultRow, _xlfn.XLOOKUP( _xlpm.dayNames, ForecastTbl[Weekday], ForecastTbl[Effective_Multiplier], 1 ), SUMPRODUCT(_xlpm.flags, _xlpm.usageRow, _xlpm.effMultRow) ), 0)} -> 2 | L19: =MAX(0, tPlan[[#This Row],[Current Stock]] - tPlan[[#This Row],[Pre-Delivery Demand]]) -> 2
A20: Protein Item A | B20: 1 | C20: 0 | D20: =MAX(0, ROUNDUP(tPlan[[#This Row],[Total Required]] - (tPlan[[#This Row],[Current Stock]] + tPlan[[#This Row],[Incoming Ordered]]), 0)) -> 8 | E20: =IF(tPlan[[#This Row],[Projected Stock Delivery]]<=0,"URGENT", IF(tPlan[[#This Row],[Order Qty]]>0,"ORDER","OK")) -> URGENT | F20: {=_xlfn.LET( _xlpm.item, tPlan[[#This Row],[Item]], _xlpm.prof, $B$5, _xlpm.usageRow, _xlfn.XLOOKUP( _xlpm.item&"|"&_xlpm.prof, UsageProfiles[Item]&"|"&UsageProfiles[Profile], UsageProfiles[[Mon]:[Sun]], 0 ), _xlpm.effMultRow, _xlfn.XLOOKUP( {"Monday","Tuesday","Wednesday","Thursday","Friday","Saturday","Sunday"}, ForecastTbl[Weekday], ForecastTbl[Effective_Multiplier], 1 ), _xlpm.coverFlagsRow, _xlfn.XLOOKUP( $B$3, DeliveryCoverage[Delivery_Day], DeliveryCoverage[[Mon]:[Sun]], 0 ), SUMPRODUCT(_xlpm.usageRow, _xlpm.effMultRow, _xlpm.coverFlagsRow) )} -> 2.0890388 | G20: {=_xlfn.LET( _xlpm.item, tPlan[[#This Row],[Item]], _xlpm.prof, $B$5, _xlpm.baseBuffer, _xlfn.XLOOKUP( _xlpm.item&"|"&_xlpm.prof, UsageProfiles[Item]&"|"&UsageProfiles[Profile], UsageProfiles[Buffer], 0 ), _xlpm.profMult, Forecast_Model!$E$15, ROUNDUP(_xlpm.baseBuffer * _xlpm.profMult, 0) )} -> 2 | H20: =tPlan[[#This Row],[Pre-Delivery Demand]] + tPlan[[#This Row],[Coverage Demand]] + tPlan[[#This Row],[Adjusted Buffer]] -> 8.0890388 | I20: {=_xlfn.LET( _xlpm.item, tPlan[[#This Row],[Item]], _xlpm.prof, $B$5, _xlpm.salesUnit, _xlfn.XLOOKUP( _xlpm.item&"|"&_xlpm.prof, UsageProfiles[Item]&"|"&UsageProfiles[Profile], UsageProfiles[Sales_per_unit], 0 ), MAX(0, tPlan[[#This Row],[Total Required]] - (tPlan[[#This Row],[Current Stock]] + tPlan[[#This Row],[Incoming Ordered]])) * _xlpm.salesUnit )} -> 3544.5194 | J20: {=_xlfn.LET( _xlpm.item, tPlan[[#This Row],[Item]], _xlpm.prof, $B$5, _xlpm.usageRow, _xlfn.XLOOKUP( _xlpm.item&"|"&_xlpm.prof, UsageProfiles[Item]&"|"&UsageProfiles[Profile], UsageProfiles[[Mon]:[Sun]], 0 ), _xlpm.effMultRow, _xlfn.XLOOKUP( {"Monday","Tuesday","Wednesday","Thursday","Friday","Saturday","Sunday"}, ForecastTbl[Weekday], ForecastTbl[Effective_Multiplier], 1 ), _xlpm.coverFlagsRow, _xlfn.XLOOKUP( $B$3, DeliveryCoverage[Delivery_Day], DeliveryCoverage[[Mon]:[Sun]], 0 ), _xlpm.covDays, SUM(_xlpm.coverFlagsRow), _xlpm.covDemand, SUMPRODUCT(_xlpm.usageRow, _xlpm.effMultRow, _xlpm.coverFlagsRow), _xlpm.dailyDemand, IF(_xlpm.covDays=0, 0, _xlpm.covDemand/_xlpm.covDays), IF(_xlpm.dailyDemand=0, "", ROUND((tPlan[[#This Row],[Current Stock]]+tPlan[[#This Row],[Incoming Ordered]])/_xlpm.dailyDemand, 1)) )} -> 1 | K20: {=ROUNDUP( _xlfn.LET( _xlpm.stDay, TRIM($B$2), _xlpm.delDay, TRIM($B$3), _xlpm.incDel, $B$4, _xlpm.dayNames, {"Monday","Tuesday","Wednesday","Thursday","Friday","Saturday","Sunday"}, _xlpm.idxSt, _xlfn.XMATCH(_xlpm.stDay, _xlpm.dayNames, 0), _xlpm.idxDel, _xlfn.XMATCH(_xlpm.delDay, _xlpm.dayNames, 0), _xlpm.days, {1,2,3,4,5,6,7}, _xlpm.idxEnd, IF(_xlpm.incDel, _xlpm.idxDel, _xlpm.idxDel-1), _xlpm.flags, IF( OR(ISNA(_xlpm.idxSt), ISNA(_xlpm.idxDel), _xlpm.idxEnd<1), {0,0,0,0,0,0,0}, IF( _xlpm.idxSt<=_xlpm.idxEnd, --(_xlpm.days>=_xlpm.idxSt)*(_xlpm.days<=_xlpm.idxEnd), --((_xlpm.days>=_xlpm.idxSt)+(_xlpm.days<=_xlpm.idxEnd)>0) ) ), _xlpm.usageRow, _xlfn.XLOOKUP( tPlan[[#This Row],[Item]]&"|"&$B$5, UsageProfiles[Item]&"|"&UsageProfiles[Profile], UsageProfiles[[Mon]:[Sun]], 0 ), _xlpm.effMultRow, _xlfn.XLOOKUP( _xlpm.dayNames, ForecastTbl[Weekday], ForecastTbl[Effective_Multiplier], 1 ), SUMPRODUCT(_xlpm.flags, _xlpm.usageRow, _xlpm.effMultRow) ), 0)} -> 4 | L20: =MAX(0, tPlan[[#This Row],[Current Stock]] - tPlan[[#This Row],[Pre-Delivery Demand]]) -> 0
A21: Frozen Item B | B21: 4 | C21: 2 | D21: =MAX(0, ROUNDUP(tPlan[[#This Row],[Total Required]] - (tPlan[[#This Row],[Current Stock]] + tPlan[[#This Row],[Incoming Ordered]]), 0)) -> 3 | E21: =IF(tPlan[[#This Row],[Projected Stock Delivery]]<=0,"URGENT", IF(tPlan[[#This Row],[Order Qty]]>0,"ORDER","OK")) -> URGENT | F21: {=_xlfn.LET( _xlpm.item, tPlan[[#This Row],[Item]], _xlpm.prof, $B$5, _xlpm.usageRow, _xlfn.XLOOKUP( _xlpm.item&"|"&_xlpm.prof, UsageProfiles[Item]&"|"&UsageProfiles[Profile], UsageProfiles[[Mon]:[Sun]], 0 ), _xlpm.effMultRow, _xlfn.XLOOKUP( {"Monday","Tuesday","Wednesday","Thursday","Friday","Saturday","Sunday"}, ForecastTbl[Weekday], ForecastTbl[Effective_Multiplier], 1 ), _xlpm.coverFlagsRow, _xlfn.XLOOKUP( $B$3, DeliveryCoverage[Delivery_Day], DeliveryCoverage[[Mon]:[Sun]], 0 ), SUMPRODUCT(_xlpm.usageRow, _xlpm.effMultRow, _xlpm.coverFlagsRow) )} -> 2.0890388 | G21: {=_xlfn.LET( _xlpm.item, tPlan[[#This Row],[Item]], _xlpm.prof, $B$5, _xlpm.baseBuffer, _xlfn.XLOOKUP( _xlpm.item&"|"&_xlpm.prof, UsageProfiles[Item]&"|"&UsageProfiles[Profile], UsageProfiles[Buffer], 0 ), _xlpm.profMult, Forecast_Model!$E$15, ROUNDUP(_xlpm.baseBuffer * _xlpm.profMult, 0) )} -> 2 | H21: =tPlan[[#This Row],[Pre-Delivery Demand]] + tPlan[[#This Row],[Coverage Demand]] + tPlan[[#This Row],[Adjusted Buffer]] -> 8.0890388 | I21: {=_xlfn.LET( _xlpm.item, tPlan[[#This Row],[Item]], _xlpm.prof, $B$5, _xlpm.salesUnit, _xlfn.XLOOKUP( _xlpm.item&"|"&_xlpm.prof, UsageProfiles[Item]&"|"&UsageProfiles[Profile], UsageProfiles[Sales_per_unit], 0 ), MAX(0, tPlan[[#This Row],[Total Required]] - (tPlan[[#This Row],[Current Stock]] + tPlan[[#This Row],[Incoming Ordered]])) * _xlpm.salesUnit )} -> 2089.0388 | J21: {=_xlfn.LET( _xlpm.item, tPlan[[#This Row],[Item]], _xlpm.prof, $B$5, _xlpm.usageRow, _xlfn.XLOOKUP( _xlpm.item&"|"&_xlpm.prof, UsageProfiles[Item]&"|"&UsageProfiles[Profile], UsageProfiles[[Mon]:[Sun]], 0 ), _xlpm.effMultRow, _xlfn.XLOOKUP( {"Monday","Tuesday","Wednesday","Thursday","Friday","Saturday","Sunday"}, ForecastTbl[Weekday], ForecastTbl[Effective_Multiplier], 1 ), _xlpm.coverFlagsRow, _xlfn.XLOOKUP( $B$3, DeliveryCoverage[Delivery_Day], DeliveryCoverage[[Mon]:[Sun]], 0 ), _xlpm.covDays, SUM(_xlpm.coverFlagsRow), _xlpm.covDemand, SUMPRODUCT(_xlpm.usageRow, _xlpm.effMultRow, _xlpm.coverFlagsRow), _xlpm.dailyDemand, IF(_xlpm.covDays=0, 0, _xlpm.covDemand/_xlpm.covDays), IF(_xlpm.dailyDemand=0, "", ROUND((tPlan[[#This Row],[Current Stock]]+tPlan[[#This Row],[Incoming Ordered]])/_xlpm.dailyDemand, 1)) )} -> 5.7 | K21: {=ROUNDUP( _xlfn.LET( _xlpm.stDay, TRIM($B$2), _xlpm.delDay, TRIM($B$3), _xlpm.incDel, $B$4, _xlpm.dayNames, {"Monday","Tuesday","Wednesday","Thursday","Friday","Saturday","Sunday"}, _xlpm.idxSt, _xlfn.XMATCH(_xlpm.stDay, _xlpm.dayNames, 0), _xlpm.idxDel, _xlfn.XMATCH(_xlpm.delDay, _xlpm.dayNames, 0), _xlpm.days, {1,2,3,4,5,6,7}, _xlpm.idxEnd, IF(_xlpm.incDel, _xlpm.idxDel, _xlpm.idxDel-1), _xlpm.flags, IF( OR(ISNA(_xlpm.idxSt), ISNA(_xlpm.idxDel), _xlpm.idxEnd<1), {0,0,0,0,0,0,0}, IF( _xlpm.idxSt<=_xlpm.idxEnd, --(_xlpm.days>=_xlpm.idxSt)*(_xlpm.days<=_xlpm.idxEnd), --((_xlpm.days>=_xlpm.idxSt)+(_xlpm.days<=_xlpm.idxEnd)>0) ) ), _xlpm.usageRow, _xlfn.XLOOKUP( tPlan[[#This Row],[Item]]&"|"&$B$5, UsageProfiles[Item]&"|"&UsageProfiles[Profile], UsageProfiles[[Mon]:[Sun]], 0 ), _xlpm.effMultRow, _xlfn.XLOOKUP( _xlpm.dayNames, ForecastTbl[Weekday], ForecastTbl[Effective_Multiplier], 1 ), SUMPRODUCT(_xlpm.flags, _xlpm.usageRow, _xlpm.effMultRow) ), 0)} -> 4 | L21: =MAX(0, tPlan[[#This Row],[Current Stock]] - tPlan[[#This Row],[Pre-Delivery Demand]]) -> 0

Sheet Data_Sales
A1: Date | B1: Weekday | C1: Sales | D1: YearWeek | E1: Week_Type
A2: 45929 | B2: Monday | C2: 3453 | D2: 2025-40 | E2: Normal Trading
A3: 45930 | B3: Tuesday | C3: 4163 | D3: 2025-40 | E3: Normal Trading
A4: 45931 | B4: Wednesday | C4: 3885 | D4: 2025-40 | E4: Normal Trading
A5: 45932 | B5: Thursday | C5: 4206 | D5: 2025-40 | E5: Normal Trading
A6: 45933 | B6: Friday | C6: 5977 | D6: 2025-40 | E6: Normal Trading
A7: 45934 | B7: Saturday | C7: 8970 | D7: 2025-40 | E7: Normal Trading
A8: 45935 | B8: Sunday | C8: 8379 | D8: 2025-40 | E8: Normal Trading
A9: 45937 | B9: Tuesday | C9: 4858 | D9: 2025-41 | E9: Normal Trading
A10: 45938 | B10: Wednesday | C10: 3401 | D10: 2025-41 | E10: Normal Trading
A11: 45939 | B11: Thursday | C11: 5726 | D11: 2025-41 | E11: Normal Trading
A12: 45940 | B12: Friday | C12: 7294 | D12: 2025-41 | E12: Normal Trading
A13: 45941 | B13: Saturday | C13: 7613 | D13: 2025-41 | E13: Normal Trading
... A197: 46138 | B197: Sunday | C197: 6490 | D197: 2026-17 | E197: Normal Trading

Sheet Setup
A3: Delivery_Day | C3: Delivery_Coverage_Flags | L3: Weekday_List | N3: Profile | O3: Multiplier
A4: Monday | C4: Delivery_Day | D4: Mon | E4: Tue | F4: Wed | G4: Thu | H4: Fri | I4: Sat | J4: Sun | L4: Monday | N4: Low | O4: 0.9
A5: Wednesday | C5: Monday | D5: 0 | E5: 1 | F5: 1 | G5: 0 | H5: 0 | I5: 0 | J5: 0 | L5: Tuesday | N5: Normal | O5: 1.05
A6: Friday | C6: Wednesday | D6: 0 | E6: 0 | F6: 0 | G6: 1 | H6: 1 | I6: 0 | J6: 0 | L6: Wednesday | N6: High | O6: 1.15
A7: Saturday | C7: Friday | D7: 1 | E7: 0 | F7: 0 | G7: 0 | H7: 0 | I7: 1 | J7: 1 | L7: Thursday
C8: Saturday | D8: 1 | E8: 0 | F8: 0 | G8: 0 | H8: 0 | I8: 0 | J8: 1 | L8: Friday
L9: Saturday
L10: Sunday
C17: Profile | D17: Min | E17: Multiplier
C18: Low | D18: 0 | E18: 0.9
C19: Normal | D19: 0.91 | E19: 1.05
C20: High | D20: 1.06 | E20: 1.15

Sheet Forecast_Model
A2: Weekly Forecast Input | D2: Weekday | E2: Forecast_Sales | F2: Baseline_Sales | G2: Raw_Multiplier | H2: Effective_Multiplier
A3: Week Start Date (Mon) | B3: 46139 | D3: Monday | E3: {=_xlfn.LET( _xlpm.wd, ForecastTbl[[#This Row],[Weekday]], _xlpm.startDate, $B$3, _xlpm.include, (tSales[Weekday]=_xlpm.wd) * (tSales[Date]<_xlpm.startDate) * (tSales[Sales]>0), _xlpm.vals, _xlfn._xlws.FILTER(tSales[Sales], _xlpm.include), _xlpm.dts, _xlfn._xlws.FILTER(tSales[Date], _xlpm.include), _xlpm.valsSorted, _xlfn.SORTBY(_xlpm.vals, _xlpm.dts, -1), _xlpm.n, ROWS(_xlpm.valsSorted), _xlpm.k, IF(_xlpm.n>=3,3,IF(_xlpm.n>=2,2,IF(_xlpm.n>=1,1,0))), _xlpm.avgN, IF(_xlpm.k=0,0, AVERAGE(_xlfn.TAKE(_xlpm.valsSorted,_xlpm.k))), CEILING(_xlpm.avgN, 100) )} -> 4600 | F3: =_xlfn.LET( _xlpm.wd, ForecastTbl[[#This Row],[Weekday]], _xlpm.startDate, $B$3, _xlpm.cutoff, _xlpm.startDate-84, AVERAGEIFS( tSales[Sales], tSales[Weekday], _xlpm.wd, tSales[Date], ">="&_xlpm.cutoff, tSales[Date], "<"&_xlpm.startDate ) ) -> 4121.6667 | G3: =IF(ForecastTbl[[#This Row],[Baseline_Sales]]=0,1,ForecastTbl[[#This Row],[Forecast_Sales]]/ForecastTbl[[#This Row],[Baseline_Sales]]) -> 1.1160534 | H3: =Forecast_Model!$E16 -> 1.171856
A4: Week End Date (Sun) | B4: =B3+6 -> 46145 | D4: Tuesday | E4: {=_xlfn.LET( _xlpm.wd, ForecastTbl[[#This Row],[Weekday]], _xlpm.startDate, $B$3, _xlpm.include, (tSales[Weekday]=_xlpm.wd) * (tSales[Date]<_xlpm.startDate) * (tSales[Sales]>0), _xlpm.vals, _xlfn._xlws.FILTER(tSales[Sales], _xlpm.include), _xlpm.dts, _xlfn._xlws.FILTER(tSales[Date], _xlpm.include), _xlpm.valsSorted, _xlfn.SORTBY(_xlpm.vals, _xlpm.dts, -1), _xlpm.n, ROWS(_xlpm.valsSorted), _xlpm.k, IF(_xlpm.n>=3,3,IF(_xlpm.n>=2,2,IF(_xlpm.n>=1,1,0))), _xlpm.avgN, IF(_xlpm.k=0,0, AVERAGE(_xlfn.TAKE(_xlpm.valsSorted,_xlpm.k))), CEILING(_xlpm.avgN, 100) )} -> 3600 | F4: =_xlfn.LET( _xlpm.wd, ForecastTbl[[#This Row],[Weekday]], _xlpm.startDate, $B$3, _xlpm.cutoff, _xlpm.startDate-84, AVERAGEIFS( tSales[Sales], tSales[Weekday], _xlpm.wd, tSales[Date], ">="&_xlpm.cutoff, tSales[Date], "<"&_xlpm.startDate ) ) -> 4038.25 | G4: =IF(ForecastTbl[[#This Row],[Baseline_Sales]]=0,1,ForecastTbl[[#This Row],[Forecast_Sales]]/ForecastTbl[[#This Row],[Baseline_Sales]]) -> 0.89147527 | H4: =Forecast_Model!$E17 -> 0.93604903
A5: Forecast Total Sales | B5: =SUM(ForecastTbl[Forecast_Sales]) -> 39400 | D5: Wednesday | E5: {=_xlfn.LET( _xlpm.wd, ForecastTbl[[#This Row],[Weekday]], _xlpm.startDate, $B$3, _xlpm.include, (tSales[Weekday]=_xlpm.wd) * (tSales[Date]<_xlpm.startDate) * (tSales[Sales]>0), _xlpm.vals, _xlfn._xlws.FILTER(tSales[Sales], _xlpm.include), _xlpm.dts, _xlfn._xlws.FILTER(tSales[Date], _xlpm.include), _xlpm.valsSorted, _xlfn.SORTBY(_xlpm.vals, _xlpm.dts, -1), _xlpm.n, ROWS(_xlpm.valsSorted), _xlpm.k, IF(_xlpm.n>=3,3,IF(_xlpm.n>=2,2,IF(_xlpm.n>=1,1,0))), _xlpm.avgN, IF(_xlpm.k=0,0, AVERAGE(_xlfn.TAKE(_xlpm.valsSorted,_xlpm.k))), CEILING(_xlpm.avgN, 100) )} -> 4100 | F5: =_xlfn.LET( _xlpm.wd, ForecastTbl[[#This Row],[Weekday]], _xlpm.startDate, $B$3, _xlpm.cutoff, _xlpm.startDate-84, AVERAGEIFS( tSales[Sales], tSales[Weekday], _xlpm.wd, tSales[Date], ">="&_xlpm.cutoff, tSales[Date], "<"&_xlpm.startDate ) ) -> 4086.3333 | G5: =IF(ForecastTbl[[#This Row],[Baseline_Sales]]=0,1,ForecastTbl[[#This Row],[Forecast_Sales]]/ForecastTbl[[#This Row],[Baseline_Sales]]) -> 1.0033445 | H5: =Forecast_Model!$E18 -> 1.0535117
D6: Thursday | E6: {=_xlfn.LET( _xlpm.wd, ForecastTbl[[#This Row],[Weekday]], _xlpm.startDate, $B$3, _xlpm.include, (tSales[Weekday]=_xlpm.wd) * (tSales[Date]<_xlpm.startDate) * (tSales[Sales]>0), _xlpm.vals, _xlfn._xlws.FILTER(tSales[Sales], _xlpm.include), _xlpm.dts, _xlfn._xlws.FILTER(tSales[Date], _xlpm.include), _xlpm.valsSorted, _xlfn.SORTBY(_xlpm.vals, _xlpm.dts, -1), _xlpm.n, ROWS(_xlpm.valsSorted), _xlpm.k, IF(_xlpm.n>=3,3,IF(_xlpm.n>=2,2,IF(_xlpm.n>=1,1,0))), _xlpm.avgN, IF(_xlpm.k=0,0, AVERAGE(_xlfn.TAKE(_xlpm.valsSorted,_xlpm.k))), CEILING(_xlpm.avgN, 100) )} -> 5800 | F6: =_xlfn.LET( _xlpm.wd, ForecastTbl[[#This Row],[Weekday]], _xlpm.startDate, $B$3, _xlpm.cutoff, _xlpm.startDate-84, AVERAGEIFS( tSales[Sales], tSales[Weekday], _xlpm.wd, tSales[Date], ">="&_xlpm.cutoff, tSales[Date], "<"&_xlpm.startDate ) ) -> 5291.75 | G6: =IF(ForecastTbl[[#This Row],[Baseline_Sales]]=0,1,ForecastTbl[[#This Row],[Forecast_Sales]]/ForecastTbl[[#This Row],[Baseline_Sales]]) -> 1.0960457 | H6: =Forecast_Model!$E19 -> 1.150848
A7: Check | B7: =SUM(ForecastTbl[Forecast_Sales]) -> 39400 | D7: Friday | E7: {=_xlfn.LET( _xlpm.wd, ForecastTbl[[#This Row],[Weekday]], _xlpm.startDate, $B$3, _xlpm.include, (tSales[Weekday]=_xlpm.wd) * (tSales[Date]<_xlpm.startDate) * (tSales[Sales]>0), _xlpm.vals, _xlfn._xlws.FILTER(tSales[Sales], _xlpm.include), _xlpm.dts, _xlfn._xlws.FILTER(tSales[Date], _xlpm.include), _xlpm.valsSorted, _xlfn.SORTBY(_xlpm.vals, _xlpm.dts, -1), _xlpm.n, ROWS(_xlpm.valsSorted), _xlpm.k, IF(_xlpm.n>=3,3,IF(_xlpm.n>=2,2,IF(_xlpm.n>=1,1,0))), _xlpm.avgN, IF(_xlpm.k=0,0, AVERAGE(_xlfn.TAKE(_xlpm.valsSorted,_xlpm.k))), CEILING(_xlpm.avgN, 100) )} -> 5800 | F7: =_xlfn.LET( _xlpm.wd, ForecastTbl[[#This Row],[Weekday]], _xlpm.startDate, $B$3, _xlpm.cutoff, _xlpm.startDate-84, AVERAGEIFS( tSales[Sales], tSales[Weekday], _xlpm.wd, tSales[Date], ">="&_xlpm.cutoff, tSales[Date], "<"&_xlpm.startDate ) ) -> 7075.1667 | G7: =IF(ForecastTbl[[#This Row],[Baseline_Sales]]=0,1,ForecastTbl[[#This Row],[Forecast_Sales]]/ForecastTbl[[#This Row],[Baseline_Sales]]) -> 0.81976867 | H7: =Forecast_Model!$E20 -> 0.86075711
A8: Difference vs Total | B8: =B5-B7 -> 0 | D8: Saturday | E8: {=_xlfn.LET( _xlpm.wd, ForecastTbl[[#This Row],[Weekday]], _xlpm.startDate, $B$3, _xlpm.include, (tSales[Weekday]=_xlpm.wd) * (tSales[Date]<_xlpm.startDate) * (tSales[Sales]>0), _xlpm.vals, _xlfn._xlws.FILTER(tSales[Sales], _xlpm.include), _xlpm.dts, _xlfn._xlws.FILTER(tSales[Date], _xlpm.include), _xlpm.valsSorted, _xlfn.SORTBY(_xlpm.vals, _xlpm.dts, -1), _xlpm.n, ROWS(_xlpm.valsSorted), _xlpm.k, IF(_xlpm.n>=3,3,IF(_xlpm.n>=2,2,IF(_xlpm.n>=1,1,0))), _xlpm.avgN, IF(_xlpm.k=0,0, AVERAGE(_xlfn.TAKE(_xlpm.valsSorted,_xlpm.k))), CEILING(_xlpm.avgN, 100) )} -> 9000 | F8: =_xlfn.LET( _xlpm.wd, ForecastTbl[[#This Row],[Weekday]], _xlpm.startDate, $B$3, _xlpm.cutoff, _xlpm.startDate-84, AVERAGEIFS( tSales[Sales], tSales[Weekday], _xlpm.wd, tSales[Date], ">="&_xlpm.cutoff, tSales[Date], "<"&_xlpm.startDate ) ) -> 8760.4167 | G8: =IF(ForecastTbl[[#This Row],[Baseline_Sales]]=0,1,ForecastTbl[[#This Row],[Forecast_Sales]]/ForecastTbl[[#This Row],[Baseline_Sales]]) -> 1.0273484 | H8: =Forecast_Model!$E21 -> 1.0787158
D9: Sunday | E9: {=_xlfn.LET( _xlpm.wd, ForecastTbl[[#This Row],[Weekday]], _xlpm.startDate, $B$3, _xlpm.include, (tSales[Weekday]=_xlpm.wd) * (tSales[Date]<_xlpm.startDate) * (tSales[Sales]>0), _xlpm.vals, _xlfn._xlws.FILTER(tSales[Sales], _xlpm.include), _xlpm.dts, _xlfn._xlws.FILTER(tSales[Date], _xlpm.include), _xlpm.valsSorted, _xlfn.SORTBY(_xlpm.vals, _xlpm.dts, -1), _xlpm.n, ROWS(_xlpm.valsSorted), _xlpm.k, IF(_xlpm.n>=3,3,IF(_xlpm.n>=2,2,IF(_xlpm.n>=1,1,0))), _xlpm.avgN, IF(_xlpm.k=0,0, AVERAGE(_xlfn.TAKE(_xlpm.valsSorted,_xlpm.k))), CEILING(_xlpm.avgN, 100) )} -> 6500 | F9: =_xlfn.LET( _xlpm.wd, ForecastTbl[[#This Row],[Weekday]], _xlpm.startDate, $B$3, _xlpm.cutoff, _xlpm.startDate-84, AVERAGEIFS( tSales[Sales], tSales[Weekday], _xlpm.wd, tSales[Date], ">="&_xlpm.cutoff, tSales[Date], "<"&_xlpm.startDate ) ) -> 7448.6667 | G9: =IF(ForecastTbl[[#This Row],[Baseline_Sales]]=0,1,ForecastTbl[[#This Row],[Forecast_Sales]]/ForecastTbl[[#This Row],[Baseline_Sales]]) -> 0.8726394 | H9: =Forecast_Model!$E22 -> 0.91627137
D11: Weekly Baseline | E11: =SUM(ForecastTbl[Baseline_Sales]) -> 40822.25
D12: Weekly Forecast | E12: =SUM(ForecastTbl[Forecast_Sales]) -> 39400
D13: Weekly Multiplier | E13: =IF(E11=0,1,E12/E11) -> 0.96515993
D14: Selected Profile | E14: {=_xlfn.LET(_xlpm.m, VALUE($E$13), _xlfn.XLOOKUP(_xlpm.m, ProfileRules[Min], ProfileRules[Profile], "High", -1) )} -> Normal
D15: Profile Multiplier | E15: =IFERROR(_xlfn.XLOOKUP($E$14, ProfileRules[Profile], ProfileRules[Multiplier], 1),1) -> 1.05
D16: Effective_Multiplier | E16: {=IFERROR(ForecastTbl[Raw_Multiplier]*$E$15,1)} -> 1.171856
E17: 0.93604903
E18: 1.0535117
E19: 1.150848
E20: 0.86075711
E21: 1.0787158
E22: 0.91627137

Sheet Usage_Rates
A1: Item | B1: Profile | C1: Sales_per_unit | D1: Mon | E1: Tue | F1: Wed | G1: Thu | H1: Fri | I1: Sat | J1: Sun | K1: Buffer | L1: Weekly_Usage | M1: Adjusted_Buffer | N1: Total_Weekly_Need | P1: Item | Q1: Avg Weekly Usage (Low) | R1: Avg Weekly Usage (Normal) | S1: Avg Weekly Usage (High)
A2: Sauce A | B2: Low | C2: 500 | D2: 2 | E2: 2 | F2: 2 | G2: 3 | H2: 3 | I2: 3 | J2: 3 | K2: 2 | L2: =UsageProfiles[[#This Row],[Mon]]+UsageProfiles[[#This Row],[Tue]]+UsageProfiles[[#This Row],[Wed]]+UsageProfiles[[#This Row],[Thu]]+UsageProfiles[[#This Row],[Fri]]+UsageProfiles[[#This Row],[Sat]]+UsageProfiles[[#This Row],[Sun]] -> 18 | M2: =ROUNDUP(UsageProfiles[[#This Row],[Buffer]]*_xlfn.XLOOKUP(UsageProfiles[[#This Row],[Profile]], DemandProfile[Profile], DemandProfile[Multiplier]),0) -> 2 | N2: =ROUNDUP(UsageProfiles[[#This Row],[Weekly_Usage]]+UsageProfiles[[#This Row],[Adjusted_Buffer]],1) -> 20 | P2: Sauce A | Q2: =SUMIFS(UsageProfiles[Weekly_Usage], UsageProfiles[Item],$P2, UsageProfiles[Profile], "Low") -> 18 | R2: =SUMIFS(UsageProfiles[Weekly_Usage], UsageProfiles[Item], $P2, UsageProfiles[Profile], "Normal") -> 18.9 | S2: =SUMIFS(UsageProfiles[Weekly_Usage], UsageProfiles[Item], $P2, UsageProfiles[Profile], "High") -> 20.7
